<?xml version="1.0" encoding="UTF-8"?>
<testng-results skipped="0" failed="6" total="6" passed="0">
  <reporter-output>
  </reporter-output>
  <suite name="Suite" duration-ms="60297" started-at="2017-10-08T13:58:44Z" finished-at="2017-10-08T13:59:44Z">
    <groups>
    </groups>
    <test name="Users_firefox6" duration-ms="60297" started-at="2017-10-08T13:58:44Z" finished-at="2017-10-08T13:59:44Z">
      <class name="USERS.User_page">
        <test-method status="PASS" signature="Loginpage(java.lang.String)[pri:0, instance:USERS.User_page@5e3a8624]" name="Loginpage" is-config="true" duration-ms="15177" started-at="2017-10-08T19:28:44Z" finished-at="2017-10-08T19:28:59Z">
          <params>
            <param index="0">
              <value>
                <![CDATA[firefox]]>
              </value>
            </param>
          </params>
          <reporter-output>
          </reporter-output>
        </test-method> <!-- Loginpage -->
        <test-method status="FAIL" signature="Login()[pri:1, instance:USERS.User_page@5e3a8624]" name="Login" duration-ms="15120" started-at="2017-10-08T19:28:59Z" finished-at="2017-10-08T19:29:14Z">
          <exception class="org.openqa.selenium.NoSuchElementException">
            <message>
              <![CDATA[Unable to locate element: {"method":"xpath","selector":".//span[@id='select2-ddlModalCompany-container' and @class='select2-selection__rendered']"}
Command duration or timeout: 54 milliseconds
For documentation on this error, please visit: http://seleniumhq.org/exceptions/no_such_element.html
Build info: version: '2.53.1', revision: 'a36b8b1', time: '2016-06-30 17:32:46'
System info: host: 'LAPTOP-P9U8PG08', ip: '192.168.1.141', os.name: 'Windows 10', os.arch: 'amd64', os.version: '10.0', java.version: '1.8.0_131'
Driver info: org.openqa.selenium.firefox.FirefoxDriver
Capabilities [{applicationCacheEnabled=true, rotatable=false, handlesAlerts=true, databaseEnabled=true, version=47.0.1, platform=WINDOWS, nativeEvents=false, acceptSslCerts=true, webStorageEnabled=true, locationContextEnabled=true, browserName=firefox, takesScreenshot=true, javascriptEnabled=true, cssSelectorsEnabled=true}]
Session ID: f740f3a6-64a2-411b-bd47-762103737e15
*** Element info: {Using=xpath, value=.//span[@id='select2-ddlModalCompany-container' and @class='select2-selection__rendered']}]]>
            </message>
            <full-stacktrace>
              <![CDATA[org.openqa.selenium.NoSuchElementException: Unable to locate element: {"method":"xpath","selector":".//span[@id='select2-ddlModalCompany-container' and @class='select2-selection__rendered']"}
Command duration or timeout: 54 milliseconds
For documentation on this error, please visit: http://seleniumhq.org/exceptions/no_such_element.html
Build info: version: '2.53.1', revision: 'a36b8b1', time: '2016-06-30 17:32:46'
System info: host: 'LAPTOP-P9U8PG08', ip: '192.168.1.141', os.name: 'Windows 10', os.arch: 'amd64', os.version: '10.0', java.version: '1.8.0_131'
Driver info: org.openqa.selenium.firefox.FirefoxDriver
Capabilities [{applicationCacheEnabled=true, rotatable=false, handlesAlerts=true, databaseEnabled=true, version=47.0.1, platform=WINDOWS, nativeEvents=false, acceptSslCerts=true, webStorageEnabled=true, locationContextEnabled=true, browserName=firefox, takesScreenshot=true, javascriptEnabled=true, cssSelectorsEnabled=true}]
Session ID: f740f3a6-64a2-411b-bd47-762103737e15
*** Element info: {Using=xpath, value=.//span[@id='select2-ddlModalCompany-container' and @class='select2-selection__rendered']}
	at sun.reflect.NativeConstructorAccessorImpl.newInstance0(Native Method)
	at sun.reflect.NativeConstructorAccessorImpl.newInstance(Unknown Source)
	at sun.reflect.DelegatingConstructorAccessorImpl.newInstance(Unknown Source)
	at java.lang.reflect.Constructor.newInstance(Unknown Source)
	at org.openqa.selenium.remote.ErrorHandler.createThrowable(ErrorHandler.java:206)
	at org.openqa.selenium.remote.ErrorHandler.throwIfResponseFailed(ErrorHandler.java:158)
	at org.openqa.selenium.remote.RemoteWebDriver.execute(RemoteWebDriver.java:678)
	at org.openqa.selenium.remote.RemoteWebDriver.findElement(RemoteWebDriver.java:363)
	at org.openqa.selenium.remote.RemoteWebDriver.findElementByXPath(RemoteWebDriver.java:500)
	at org.openqa.selenium.By$ByXPath.findElement(By.java:361)
	at org.openqa.selenium.remote.RemoteWebDriver.findElement(RemoteWebDriver.java:355)
	at USERS.User_page.Login(User_page.java:168)
	at sun.reflect.NativeMethodAccessorImpl.invoke0(Native Method)
	at sun.reflect.NativeMethodAccessorImpl.invoke(Unknown Source)
	at sun.reflect.DelegatingMethodAccessorImpl.invoke(Unknown Source)
	at java.lang.reflect.Method.invoke(Unknown Source)
	at org.testng.internal.MethodInvocationHelper.invokeMethod(MethodInvocationHelper.java:85)
	at org.testng.internal.Invoker.invokeMethod(Invoker.java:639)
	at org.testng.internal.Invoker.invokeTestMethod(Invoker.java:816)
	at org.testng.internal.Invoker.invokeTestMethods(Invoker.java:1124)
	at org.testng.internal.TestMethodWorker.invokeTestMethods(TestMethodWorker.java:125)
	at org.testng.internal.TestMethodWorker.run(TestMethodWorker.java:108)
	at org.testng.TestRunner.privateRun(TestRunner.java:774)
	at org.testng.TestRunner.run(TestRunner.java:624)
	at org.testng.SuiteRunner.runTest(SuiteRunner.java:359)
	at org.testng.SuiteRunner.runSequentially(SuiteRunner.java:354)
	at org.testng.SuiteRunner.privateRun(SuiteRunner.java:312)
	at org.testng.SuiteRunner.run(SuiteRunner.java:261)
	at org.testng.SuiteRunnerWorker.runSuite(SuiteRunnerWorker.java:52)
	at org.testng.SuiteRunnerWorker.run(SuiteRunnerWorker.java:86)
	at org.testng.TestNG.runSuitesSequentially(TestNG.java:1215)
	at org.testng.TestNG.runSuitesLocally(TestNG.java:1140)
	at org.testng.TestNG.run(TestNG.java:1048)
	at org.testng.remote.AbstractRemoteTestNG.run(AbstractRemoteTestNG.java:114)
	at org.testng.remote.RemoteTestNG.initAndRun(RemoteTestNG.java:251)
	at org.testng.remote.RemoteTestNG.main(RemoteTestNG.java:77)
Caused by: org.openqa.selenium.NoSuchElementException: Unable to locate element: {"method":"xpath","selector":".//span[@id='select2-ddlModalCompany-container' and @class='select2-selection__rendered']"}
For documentation on this error, please visit: http://seleniumhq.org/exceptions/no_such_element.html
Build info: version: '2.53.1', revision: 'a36b8b1', time: '2016-06-30 17:32:46'
System info: host: 'LAPTOP-P9U8PG08', ip: '192.168.1.141', os.name: 'Windows 10', os.arch: 'amd64', os.version: '10.0', java.version: '1.8.0_131'
Driver info: driver.version: unknown
	at <anonymous class>.FirefoxDriver.prototype.findElementInternal_(file:///C:/Users/MANIVA~1/AppData/Local/Temp/anonymous5162659380718710700webdriver-profile/extensions/fxdriver@googlecode.com/components/driver-component.js:10770)
	at <anonymous class>.FirefoxDriver.prototype.findElement(file:///C:/Users/MANIVA~1/AppData/Local/Temp/anonymous5162659380718710700webdriver-profile/extensions/fxdriver@googlecode.com/components/driver-component.js:10779)
	at <anonymous class>.DelayedCommand.prototype.executeInternal_/h(file:///C:/Users/MANIVA~1/AppData/Local/Temp/anonymous5162659380718710700webdriver-profile/extensions/fxdriver@googlecode.com/components/command-processor.js:12661)
	at <anonymous class>.DelayedCommand.prototype.executeInternal_(file:///C:/Users/MANIVA~1/AppData/Local/Temp/anonymous5162659380718710700webdriver-profile/extensions/fxdriver@googlecode.com/components/command-processor.js:12666)
	at <anonymous class>.DelayedCommand.prototype.execute/<(file:///C:/Users/MANIVA~1/AppData/Local/Temp/anonymous5162659380718710700webdriver-profile/extensions/fxdriver@googlecode.com/components/command-processor.js:12608)
]]>
            </full-stacktrace>
          </exception> <!-- org.openqa.selenium.NoSuchElementException -->
          <reporter-output>
          </reporter-output>
        </test-method> <!-- Login -->
        <test-method status="FAIL" signature="User_Submenu()[pri:2, instance:USERS.User_page@5e3a8624]" name="User_Submenu" duration-ms="18780" started-at="2017-10-08T19:29:14Z" finished-at="2017-10-08T19:29:33Z">
          <exception class="java.lang.AssertionError">
            <message>
              <![CDATA[expected [null] but found [User]]]>
            </message>
            <full-stacktrace>
              <![CDATA[java.lang.AssertionError: expected [null] but found [User]
	at org.testng.Assert.fail(Assert.java:94)
	at org.testng.Assert.failNotEquals(Assert.java:496)
	at org.testng.Assert.assertEquals(Assert.java:116)
	at org.testng.Assert.assertEquals(Assert.java:178)
	at org.testng.Assert.assertEquals(Assert.java:188)
	at USERS.User_page.User_Submenu(User_page.java:222)
	at sun.reflect.NativeMethodAccessorImpl.invoke0(Native Method)
	at sun.reflect.NativeMethodAccessorImpl.invoke(Unknown Source)
	at sun.reflect.DelegatingMethodAccessorImpl.invoke(Unknown Source)
	at java.lang.reflect.Method.invoke(Unknown Source)
	at org.testng.internal.MethodInvocationHelper.invokeMethod(MethodInvocationHelper.java:85)
	at org.testng.internal.Invoker.invokeMethod(Invoker.java:639)
	at org.testng.internal.Invoker.invokeTestMethod(Invoker.java:816)
	at org.testng.internal.Invoker.invokeTestMethods(Invoker.java:1124)
	at org.testng.internal.TestMethodWorker.invokeTestMethods(TestMethodWorker.java:125)
	at org.testng.internal.TestMethodWorker.run(TestMethodWorker.java:108)
	at org.testng.TestRunner.privateRun(TestRunner.java:774)
	at org.testng.TestRunner.run(TestRunner.java:624)
	at org.testng.SuiteRunner.runTest(SuiteRunner.java:359)
	at org.testng.SuiteRunner.runSequentially(SuiteRunner.java:354)
	at org.testng.SuiteRunner.privateRun(SuiteRunner.java:312)
	at org.testng.SuiteRunner.run(SuiteRunner.java:261)
	at org.testng.SuiteRunnerWorker.runSuite(SuiteRunnerWorker.java:52)
	at org.testng.SuiteRunnerWorker.run(SuiteRunnerWorker.java:86)
	at org.testng.TestNG.runSuitesSequentially(TestNG.java:1215)
	at org.testng.TestNG.runSuitesLocally(TestNG.java:1140)
	at org.testng.TestNG.run(TestNG.java:1048)
	at org.testng.remote.AbstractRemoteTestNG.run(AbstractRemoteTestNG.java:114)
	at org.testng.remote.RemoteTestNG.initAndRun(RemoteTestNG.java:251)
	at org.testng.remote.RemoteTestNG.main(RemoteTestNG.java:77)
]]>
            </full-stacktrace>
          </exception> <!-- java.lang.AssertionError -->
          <reporter-output>
          </reporter-output>
        </test-method> <!-- User_Submenu -->
        <test-method status="FAIL" signature="Customer_page()[pri:3, instance:USERS.User_page@5e3a8624]" name="Customer_page" duration-ms="2050" started-at="2017-10-08T19:29:33Z" finished-at="2017-10-08T19:29:35Z">
          <exception class="java.lang.AssertionError">
            <message>
              <![CDATA[expected [null] but found [User]]]>
            </message>
            <full-stacktrace>
              <![CDATA[java.lang.AssertionError: expected [null] but found [User]
	at org.testng.Assert.fail(Assert.java:94)
	at org.testng.Assert.failNotEquals(Assert.java:496)
	at org.testng.Assert.assertEquals(Assert.java:116)
	at org.testng.Assert.assertEquals(Assert.java:178)
	at org.testng.Assert.assertEquals(Assert.java:188)
	at USERS.User_page.Customer_page(User_page.java:273)
	at sun.reflect.NativeMethodAccessorImpl.invoke0(Native Method)
	at sun.reflect.NativeMethodAccessorImpl.invoke(Unknown Source)
	at sun.reflect.DelegatingMethodAccessorImpl.invoke(Unknown Source)
	at java.lang.reflect.Method.invoke(Unknown Source)
	at org.testng.internal.MethodInvocationHelper.invokeMethod(MethodInvocationHelper.java:85)
	at org.testng.internal.Invoker.invokeMethod(Invoker.java:639)
	at org.testng.internal.Invoker.invokeTestMethod(Invoker.java:816)
	at org.testng.internal.Invoker.invokeTestMethods(Invoker.java:1124)
	at org.testng.internal.TestMethodWorker.invokeTestMethods(TestMethodWorker.java:125)
	at org.testng.internal.TestMethodWorker.run(TestMethodWorker.java:108)
	at org.testng.TestRunner.privateRun(TestRunner.java:774)
	at org.testng.TestRunner.run(TestRunner.java:624)
	at org.testng.SuiteRunner.runTest(SuiteRunner.java:359)
	at org.testng.SuiteRunner.runSequentially(SuiteRunner.java:354)
	at org.testng.SuiteRunner.privateRun(SuiteRunner.java:312)
	at org.testng.SuiteRunner.run(SuiteRunner.java:261)
	at org.testng.SuiteRunnerWorker.runSuite(SuiteRunnerWorker.java:52)
	at org.testng.SuiteRunnerWorker.run(SuiteRunnerWorker.java:86)
	at org.testng.TestNG.runSuitesSequentially(TestNG.java:1215)
	at org.testng.TestNG.runSuitesLocally(TestNG.java:1140)
	at org.testng.TestNG.run(TestNG.java:1048)
	at org.testng.remote.AbstractRemoteTestNG.run(AbstractRemoteTestNG.java:114)
	at org.testng.remote.RemoteTestNG.initAndRun(RemoteTestNG.java:251)
	at org.testng.remote.RemoteTestNG.main(RemoteTestNG.java:77)
]]>
            </full-stacktrace>
          </exception> <!-- java.lang.AssertionError -->
          <reporter-output>
          </reporter-output>
        </test-method> <!-- Customer_page -->
        <test-method status="FAIL" signature="Customer_Addrecord_button()[pri:4, instance:USERS.User_page@5e3a8624]" name="Customer_Addrecord_button" duration-ms="43" started-at="2017-10-08T19:29:35Z" finished-at="2017-10-08T19:29:35Z">
          <exception class="java.lang.AssertionError">
            <message>
              <![CDATA[expected [null] but found [Add Record]]]>
            </message>
            <full-stacktrace>
              <![CDATA[java.lang.AssertionError: expected [null] but found [Add Record]
	at org.testng.Assert.fail(Assert.java:94)
	at org.testng.Assert.failNotEquals(Assert.java:496)
	at org.testng.Assert.assertEquals(Assert.java:116)
	at org.testng.Assert.assertEquals(Assert.java:178)
	at org.testng.Assert.assertEquals(Assert.java:188)
	at USERS.User_page.Customer_Addrecord_button(User_page.java:317)
	at sun.reflect.NativeMethodAccessorImpl.invoke0(Native Method)
	at sun.reflect.NativeMethodAccessorImpl.invoke(Unknown Source)
	at sun.reflect.DelegatingMethodAccessorImpl.invoke(Unknown Source)
	at java.lang.reflect.Method.invoke(Unknown Source)
	at org.testng.internal.MethodInvocationHelper.invokeMethod(MethodInvocationHelper.java:85)
	at org.testng.internal.Invoker.invokeMethod(Invoker.java:639)
	at org.testng.internal.Invoker.invokeTestMethod(Invoker.java:816)
	at org.testng.internal.Invoker.invokeTestMethods(Invoker.java:1124)
	at org.testng.internal.TestMethodWorker.invokeTestMethods(TestMethodWorker.java:125)
	at org.testng.internal.TestMethodWorker.run(TestMethodWorker.java:108)
	at org.testng.TestRunner.privateRun(TestRunner.java:774)
	at org.testng.TestRunner.run(TestRunner.java:624)
	at org.testng.SuiteRunner.runTest(SuiteRunner.java:359)
	at org.testng.SuiteRunner.runSequentially(SuiteRunner.java:354)
	at org.testng.SuiteRunner.privateRun(SuiteRunner.java:312)
	at org.testng.SuiteRunner.run(SuiteRunner.java:261)
	at org.testng.SuiteRunnerWorker.runSuite(SuiteRunnerWorker.java:52)
	at org.testng.SuiteRunnerWorker.run(SuiteRunnerWorker.java:86)
	at org.testng.TestNG.runSuitesSequentially(TestNG.java:1215)
	at org.testng.TestNG.runSuitesLocally(TestNG.java:1140)
	at org.testng.TestNG.run(TestNG.java:1048)
	at org.testng.remote.AbstractRemoteTestNG.run(AbstractRemoteTestNG.java:114)
	at org.testng.remote.RemoteTestNG.initAndRun(RemoteTestNG.java:251)
	at org.testng.remote.RemoteTestNG.main(RemoteTestNG.java:77)
]]>
            </full-stacktrace>
          </exception> <!-- java.lang.AssertionError -->
          <reporter-output>
          </reporter-output>
        </test-method> <!-- Customer_Addrecord_button -->
        <test-method status="FAIL" signature="AddRecord_Alertmessage()[pri:5, instance:USERS.User_page@5e3a8624]" name="AddRecord_Alertmessage" duration-ms="2052" started-at="2017-10-08T19:29:35Z" finished-at="2017-10-08T19:29:37Z">
          <exception class="java.lang.NullPointerException">
            <full-stacktrace>
              <![CDATA[java.lang.NullPointerException
	at USERS.User_page.AddRecord_Alertmessage(User_page.java:369)
	at sun.reflect.NativeMethodAccessorImpl.invoke0(Native Method)
	at sun.reflect.NativeMethodAccessorImpl.invoke(Unknown Source)
	at sun.reflect.DelegatingMethodAccessorImpl.invoke(Unknown Source)
	at java.lang.reflect.Method.invoke(Unknown Source)
	at org.testng.internal.MethodInvocationHelper.invokeMethod(MethodInvocationHelper.java:85)
	at org.testng.internal.Invoker.invokeMethod(Invoker.java:639)
	at org.testng.internal.Invoker.invokeTestMethod(Invoker.java:816)
	at org.testng.internal.Invoker.invokeTestMethods(Invoker.java:1124)
	at org.testng.internal.TestMethodWorker.invokeTestMethods(TestMethodWorker.java:125)
	at org.testng.internal.TestMethodWorker.run(TestMethodWorker.java:108)
	at org.testng.TestRunner.privateRun(TestRunner.java:774)
	at org.testng.TestRunner.run(TestRunner.java:624)
	at org.testng.SuiteRunner.runTest(SuiteRunner.java:359)
	at org.testng.SuiteRunner.runSequentially(SuiteRunner.java:354)
	at org.testng.SuiteRunner.privateRun(SuiteRunner.java:312)
	at org.testng.SuiteRunner.run(SuiteRunner.java:261)
	at org.testng.SuiteRunnerWorker.runSuite(SuiteRunnerWorker.java:52)
	at org.testng.SuiteRunnerWorker.run(SuiteRunnerWorker.java:86)
	at org.testng.TestNG.runSuitesSequentially(TestNG.java:1215)
	at org.testng.TestNG.runSuitesLocally(TestNG.java:1140)
	at org.testng.TestNG.run(TestNG.java:1048)
	at org.testng.remote.AbstractRemoteTestNG.run(AbstractRemoteTestNG.java:114)
	at org.testng.remote.RemoteTestNG.initAndRun(RemoteTestNG.java:251)
	at org.testng.remote.RemoteTestNG.main(RemoteTestNG.java:77)
]]>
            </full-stacktrace>
          </exception> <!-- java.lang.NullPointerException -->
          <reporter-output>
          </reporter-output>
        </test-method> <!-- AddRecord_Alertmessage -->
        <test-method status="FAIL" signature="Cancel_button()[pri:6, instance:USERS.User_page@5e3a8624]" name="Cancel_button" duration-ms="6053" started-at="2017-10-08T19:29:37Z" finished-at="2017-10-08T19:29:43Z">
          <exception class="java.lang.AssertionError">
            <message>
              <![CDATA[expected [null] but found [User]]]>
            </message>
            <full-stacktrace>
              <![CDATA[java.lang.AssertionError: expected [null] but found [User]
	at org.testng.Assert.fail(Assert.java:94)
	at org.testng.Assert.failNotEquals(Assert.java:496)
	at org.testng.Assert.assertEquals(Assert.java:116)
	at org.testng.Assert.assertEquals(Assert.java:178)
	at org.testng.Assert.assertEquals(Assert.java:188)
	at USERS.User_page.Cancel_button(User_page.java:417)
	at sun.reflect.NativeMethodAccessorImpl.invoke0(Native Method)
	at sun.reflect.NativeMethodAccessorImpl.invoke(Unknown Source)
	at sun.reflect.DelegatingMethodAccessorImpl.invoke(Unknown Source)
	at java.lang.reflect.Method.invoke(Unknown Source)
	at org.testng.internal.MethodInvocationHelper.invokeMethod(MethodInvocationHelper.java:85)
	at org.testng.internal.Invoker.invokeMethod(Invoker.java:639)
	at org.testng.internal.Invoker.invokeTestMethod(Invoker.java:816)
	at org.testng.internal.Invoker.invokeTestMethods(Invoker.java:1124)
	at org.testng.internal.TestMethodWorker.invokeTestMethods(TestMethodWorker.java:125)
	at org.testng.internal.TestMethodWorker.run(TestMethodWorker.java:108)
	at org.testng.TestRunner.privateRun(TestRunner.java:774)
	at org.testng.TestRunner.run(TestRunner.java:624)
	at org.testng.SuiteRunner.runTest(SuiteRunner.java:359)
	at org.testng.SuiteRunner.runSequentially(SuiteRunner.java:354)
	at org.testng.SuiteRunner.privateRun(SuiteRunner.java:312)
	at org.testng.SuiteRunner.run(SuiteRunner.java:261)
	at org.testng.SuiteRunnerWorker.runSuite(SuiteRunnerWorker.java:52)
	at org.testng.SuiteRunnerWorker.run(SuiteRunnerWorker.java:86)
	at org.testng.TestNG.runSuitesSequentially(TestNG.java:1215)
	at org.testng.TestNG.runSuitesLocally(TestNG.java:1140)
	at org.testng.TestNG.run(TestNG.java:1048)
	at org.testng.remote.AbstractRemoteTestNG.run(AbstractRemoteTestNG.java:114)
	at org.testng.remote.RemoteTestNG.initAndRun(RemoteTestNG.java:251)
	at org.testng.remote.RemoteTestNG.main(RemoteTestNG.java:77)
]]>
            </full-stacktrace>
          </exception> <!-- java.lang.AssertionError -->
          <reporter-output>
          </reporter-output>
        </test-method> <!-- Cancel_button -->
        <test-method status="PASS" signature="getup1()[pri:0, instance:USERS.User_page@5e3a8624]" name="getup1" is-config="true" duration-ms="960" started-at="2017-10-08T19:29:43Z" finished-at="2017-10-08T19:29:44Z">
          <reporter-output>
          </reporter-output>
        </test-method> <!-- getup1 -->
      </class> <!-- USERS.User_page -->
    </test> <!-- Users_firefox6 -->
  </suite> <!-- Suite -->
</testng-results>
