<?xml version="1.0" encoding="UTF-8"?>
<!-- Generated by org.testng.reporters.JUnitReportReporter -->
<testsuite hostname="LAPTOP-P9U8PG08" name="USERS.User_page" tests="6" failures="4" timestamp="8 Oct 2017 13:59:45 GMT" time="44.098" errors="2">
  <testcase name="Customer_page" time="2.050" classname="USERS.User_page">
    <failure type="java.lang.AssertionError" message="expected [null] but found [User]">
      <![CDATA[java.lang.AssertionError: expected [null] but found [User]
	at org.testng.Assert.fail(Assert.java:94)
	at org.testng.Assert.failNotEquals(Assert.java:496)
	at org.testng.Assert.assertEquals(Assert.java:116)
	at org.testng.Assert.assertEquals(Assert.java:178)
	at org.testng.Assert.assertEquals(Assert.java:188)
	at USERS.User_page.Customer_page(User_page.java:273)
	at sun.reflect.NativeMethodAccessorImpl.invoke0(Native Method)
	at sun.reflect.NativeMethodAccessorImpl.invoke(Unknown Source)
	at sun.reflect.DelegatingMethodAccessorImpl.invoke(Unknown Source)
	at java.lang.reflect.Method.invoke(Unknown Source)
	at org.testng.internal.MethodInvocationHelper.invokeMethod(MethodInvocationHelper.java:85)
	at org.testng.internal.Invoker.invokeMethod(Invoker.java:639)
	at org.testng.internal.Invoker.invokeTestMethod(Invoker.java:816)
	at org.testng.internal.Invoker.invokeTestMethods(Invoker.java:1124)
	at org.testng.internal.TestMethodWorker.invokeTestMethods(TestMethodWorker.java:125)
	at org.testng.internal.TestMethodWorker.run(TestMethodWorker.java:108)
	at org.testng.TestRunner.privateRun(TestRunner.java:774)
	at org.testng.TestRunner.run(TestRunner.java:624)
	at org.testng.SuiteRunner.runTest(SuiteRunner.java:359)
	at org.testng.SuiteRunner.runSequentially(SuiteRunner.java:354)
	at org.testng.SuiteRunner.privateRun(SuiteRunner.java:312)
	at org.testng.SuiteRunner.run(SuiteRunner.java:261)
	at org.testng.SuiteRunnerWorker.runSuite(SuiteRunnerWorker.java:52)
	at org.testng.SuiteRunnerWorker.run(SuiteRunnerWorker.java:86)
	at org.testng.TestNG.runSuitesSequentially(TestNG.java:1215)
	at org.testng.TestNG.runSuitesLocally(TestNG.java:1140)
	at org.testng.TestNG.run(TestNG.java:1048)
	at org.testng.remote.AbstractRemoteTestNG.run(AbstractRemoteTestNG.java:114)
	at org.testng.remote.RemoteTestNG.initAndRun(RemoteTestNG.java:251)
	at org.testng.remote.RemoteTestNG.main(RemoteTestNG.java:77)
]]>
    </failure>
  </testcase> <!-- Customer_page -->
  <testcase name="Cancel_button" time="6.053" classname="USERS.User_page">
    <failure type="java.lang.AssertionError" message="expected [null] but found [User]">
      <![CDATA[java.lang.AssertionError: expected [null] but found [User]
	at org.testng.Assert.fail(Assert.java:94)
	at org.testng.Assert.failNotEquals(Assert.java:496)
	at org.testng.Assert.assertEquals(Assert.java:116)
	at org.testng.Assert.assertEquals(Assert.java:178)
	at org.testng.Assert.assertEquals(Assert.java:188)
	at USERS.User_page.Cancel_button(User_page.java:417)
	at sun.reflect.NativeMethodAccessorImpl.invoke0(Native Method)
	at sun.reflect.NativeMethodAccessorImpl.invoke(Unknown Source)
	at sun.reflect.DelegatingMethodAccessorImpl.invoke(Unknown Source)
	at java.lang.reflect.Method.invoke(Unknown Source)
	at org.testng.internal.MethodInvocationHelper.invokeMethod(MethodInvocationHelper.java:85)
	at org.testng.internal.Invoker.invokeMethod(Invoker.java:639)
	at org.testng.internal.Invoker.invokeTestMethod(Invoker.java:816)
	at org.testng.internal.Invoker.invokeTestMethods(Invoker.java:1124)
	at org.testng.internal.TestMethodWorker.invokeTestMethods(TestMethodWorker.java:125)
	at org.testng.internal.TestMethodWorker.run(TestMethodWorker.java:108)
	at org.testng.TestRunner.privateRun(TestRunner.java:774)
	at org.testng.TestRunner.run(TestRunner.java:624)
	at org.testng.SuiteRunner.runTest(SuiteRunner.java:359)
	at org.testng.SuiteRunner.runSequentially(SuiteRunner.java:354)
	at org.testng.SuiteRunner.privateRun(SuiteRunner.java:312)
	at org.testng.SuiteRunner.run(SuiteRunner.java:261)
	at org.testng.SuiteRunnerWorker.runSuite(SuiteRunnerWorker.java:52)
	at org.testng.SuiteRunnerWorker.run(SuiteRunnerWorker.java:86)
	at org.testng.TestNG.runSuitesSequentially(TestNG.java:1215)
	at org.testng.TestNG.runSuitesLocally(TestNG.java:1140)
	at org.testng.TestNG.run(TestNG.java:1048)
	at org.testng.remote.AbstractRemoteTestNG.run(AbstractRemoteTestNG.java:114)
	at org.testng.remote.RemoteTestNG.initAndRun(RemoteTestNG.java:251)
	at org.testng.remote.RemoteTestNG.main(RemoteTestNG.java:77)
]]>
    </failure>
  </testcase> <!-- Cancel_button -->
  <testcase name="Login" time="15.120" classname="USERS.User_page">
    <error type="org.openqa.selenium.NoSuchElementException" message="Unable to locate element: {&quot;method&quot;:&quot;xpath&quot;,&quot;selector&quot;:&quot;.//span[@id=&#039;select2-ddlModalCompany-container&#039; and @class=&#039;select2-selection__rendered&#039;]&quot;}
Command duration or timeout: 54 milliseconds
For documentation on this error, please visit: http://seleniumhq.org/exceptions/no_such_element.html
Build info: version: &#039;2.53.1&#039;, revision: &#039;a36b8b1&#039;, time: &#039;2016-06-30 17:32:46&#039;
System info: host: &#039;LAPTOP-P9U8PG08&#039;, ip: &#039;192.168.1.141&#039;, os.name: &#039;Windows 10&#039;, os.arch: &#039;amd64&#039;, os.version: &#039;10.0&#039;, java.version: &#039;1.8.0_131&#039;
Driver info: org.openqa.selenium.firefox.FirefoxDriver
Capabilities [{applicationCacheEnabled=true, rotatable=false, handlesAlerts=true, databaseEnabled=true, version=47.0.1, platform=WINDOWS, nativeEvents=false, acceptSslCerts=true, webStorageEnabled=true, locationContextEnabled=true, browserName=firefox, takesScreenshot=true, javascriptEnabled=true, cssSelectorsEnabled=true}]
Session ID: f740f3a6-64a2-411b-bd47-762103737e15
*** Element info: {Using=xpath, value=.//span[@id=&#039;select2-ddlModalCompany-container&#039; and @class=&#039;select2-selection__rendered&#039;]}">
      <![CDATA[org.openqa.selenium.NoSuchElementException: Unable to locate element: {"method":"xpath","selector":".//span[@id='select2-ddlModalCompany-container' and @class='select2-selection__rendered']"}
Command duration or timeout: 54 milliseconds
For documentation on this error, please visit: http://seleniumhq.org/exceptions/no_such_element.html
Build info: version: '2.53.1', revision: 'a36b8b1', time: '2016-06-30 17:32:46'
System info: host: 'LAPTOP-P9U8PG08', ip: '192.168.1.141', os.name: 'Windows 10', os.arch: 'amd64', os.version: '10.0', java.version: '1.8.0_131'
Driver info: org.openqa.selenium.firefox.FirefoxDriver
Capabilities [{applicationCacheEnabled=true, rotatable=false, handlesAlerts=true, databaseEnabled=true, version=47.0.1, platform=WINDOWS, nativeEvents=false, acceptSslCerts=true, webStorageEnabled=true, locationContextEnabled=true, browserName=firefox, takesScreenshot=true, javascriptEnabled=true, cssSelectorsEnabled=true}]
Session ID: f740f3a6-64a2-411b-bd47-762103737e15
*** Element info: {Using=xpath, value=.//span[@id='select2-ddlModalCompany-container' and @class='select2-selection__rendered']}
	at sun.reflect.NativeConstructorAccessorImpl.newInstance0(Native Method)
	at sun.reflect.NativeConstructorAccessorImpl.newInstance(Unknown Source)
	at sun.reflect.DelegatingConstructorAccessorImpl.newInstance(Unknown Source)
	at java.lang.reflect.Constructor.newInstance(Unknown Source)
	at org.openqa.selenium.remote.ErrorHandler.createThrowable(ErrorHandler.java:206)
	at org.openqa.selenium.remote.ErrorHandler.throwIfResponseFailed(ErrorHandler.java:158)
	at org.openqa.selenium.remote.RemoteWebDriver.execute(RemoteWebDriver.java:678)
	at org.openqa.selenium.remote.RemoteWebDriver.findElement(RemoteWebDriver.java:363)
	at org.openqa.selenium.remote.RemoteWebDriver.findElementByXPath(RemoteWebDriver.java:500)
	at org.openqa.selenium.By$ByXPath.findElement(By.java:361)
	at org.openqa.selenium.remote.RemoteWebDriver.findElement(RemoteWebDriver.java:355)
	at USERS.User_page.Login(User_page.java:168)
	at sun.reflect.NativeMethodAccessorImpl.invoke0(Native Method)
	at sun.reflect.NativeMethodAccessorImpl.invoke(Unknown Source)
	at sun.reflect.DelegatingMethodAccessorImpl.invoke(Unknown Source)
	at java.lang.reflect.Method.invoke(Unknown Source)
	at org.testng.internal.MethodInvocationHelper.invokeMethod(MethodInvocationHelper.java:85)
	at org.testng.internal.Invoker.invokeMethod(Invoker.java:639)
	at org.testng.internal.Invoker.invokeTestMethod(Invoker.java:816)
	at org.testng.internal.Invoker.invokeTestMethods(Invoker.java:1124)
	at org.testng.internal.TestMethodWorker.invokeTestMethods(TestMethodWorker.java:125)
	at org.testng.internal.TestMethodWorker.run(TestMethodWorker.java:108)
	at org.testng.TestRunner.privateRun(TestRunner.java:774)
	at org.testng.TestRunner.run(TestRunner.java:624)
	at org.testng.SuiteRunner.runTest(SuiteRunner.java:359)
	at org.testng.SuiteRunner.runSequentially(SuiteRunner.java:354)
	at org.testng.SuiteRunner.privateRun(SuiteRunner.java:312)
	at org.testng.SuiteRunner.run(SuiteRunner.java:261)
	at org.testng.SuiteRunnerWorker.runSuite(SuiteRunnerWorker.java:52)
	at org.testng.SuiteRunnerWorker.run(SuiteRunnerWorker.java:86)
	at org.testng.TestNG.runSuitesSequentially(TestNG.java:1215)
	at org.testng.TestNG.runSuitesLocally(TestNG.java:1140)
	at org.testng.TestNG.run(TestNG.java:1048)
	at org.testng.remote.AbstractRemoteTestNG.run(AbstractRemoteTestNG.java:114)
	at org.testng.remote.RemoteTestNG.initAndRun(RemoteTestNG.java:251)
	at org.testng.remote.RemoteTestNG.main(RemoteTestNG.java:77)
Caused by: org.openqa.selenium.NoSuchElementException: Unable to locate element: {"method":"xpath","selector":".//span[@id='select2-ddlModalCompany-container' and @class='select2-selection__rendered']"}
For documentation on this error, please visit: http://seleniumhq.org/exceptions/no_such_element.html
Build info: version: '2.53.1', revision: 'a36b8b1', time: '2016-06-30 17:32:46'
System info: host: 'LAPTOP-P9U8PG08', ip: '192.168.1.141', os.name: 'Windows 10', os.arch: 'amd64', os.version: '10.0', java.version: '1.8.0_131'
Driver info: driver.version: unknown
	at <anonymous class>.FirefoxDriver.prototype.findElementInternal_(file:///C:/Users/MANIVA~1/AppData/Local/Temp/anonymous5162659380718710700webdriver-profile/extensions/fxdriver@googlecode.com/components/driver-component.js:10770)
	at <anonymous class>.FirefoxDriver.prototype.findElement(file:///C:/Users/MANIVA~1/AppData/Local/Temp/anonymous5162659380718710700webdriver-profile/extensions/fxdriver@googlecode.com/components/driver-component.js:10779)
	at <anonymous class>.DelayedCommand.prototype.executeInternal_/h(file:///C:/Users/MANIVA~1/AppData/Local/Temp/anonymous5162659380718710700webdriver-profile/extensions/fxdriver@googlecode.com/components/command-processor.js:12661)
	at <anonymous class>.DelayedCommand.prototype.executeInternal_(file:///C:/Users/MANIVA~1/AppData/Local/Temp/anonymous5162659380718710700webdriver-profile/extensions/fxdriver@googlecode.com/components/command-processor.js:12666)
	at <anonymous class>.DelayedCommand.prototype.execute/<(file:///C:/Users/MANIVA~1/AppData/Local/Temp/anonymous5162659380718710700webdriver-profile/extensions/fxdriver@googlecode.com/components/command-processor.js:12608)
]]>
    </error>
  </testcase> <!-- Login -->
  <testcase name="User_Submenu" time="18.780" classname="USERS.User_page">
    <failure type="java.lang.AssertionError" message="expected [null] but found [User]">
      <![CDATA[java.lang.AssertionError: expected [null] but found [User]
	at org.testng.Assert.fail(Assert.java:94)
	at org.testng.Assert.failNotEquals(Assert.java:496)
	at org.testng.Assert.assertEquals(Assert.java:116)
	at org.testng.Assert.assertEquals(Assert.java:178)
	at org.testng.Assert.assertEquals(Assert.java:188)
	at USERS.User_page.User_Submenu(User_page.java:222)
	at sun.reflect.NativeMethodAccessorImpl.invoke0(Native Method)
	at sun.reflect.NativeMethodAccessorImpl.invoke(Unknown Source)
	at sun.reflect.DelegatingMethodAccessorImpl.invoke(Unknown Source)
	at java.lang.reflect.Method.invoke(Unknown Source)
	at org.testng.internal.MethodInvocationHelper.invokeMethod(MethodInvocationHelper.java:85)
	at org.testng.internal.Invoker.invokeMethod(Invoker.java:639)
	at org.testng.internal.Invoker.invokeTestMethod(Invoker.java:816)
	at org.testng.internal.Invoker.invokeTestMethods(Invoker.java:1124)
	at org.testng.internal.TestMethodWorker.invokeTestMethods(TestMethodWorker.java:125)
	at org.testng.internal.TestMethodWorker.run(TestMethodWorker.java:108)
	at org.testng.TestRunner.privateRun(TestRunner.java:774)
	at org.testng.TestRunner.run(TestRunner.java:624)
	at org.testng.SuiteRunner.runTest(SuiteRunner.java:359)
	at org.testng.SuiteRunner.runSequentially(SuiteRunner.java:354)
	at org.testng.SuiteRunner.privateRun(SuiteRunner.java:312)
	at org.testng.SuiteRunner.run(SuiteRunner.java:261)
	at org.testng.SuiteRunnerWorker.runSuite(SuiteRunnerWorker.java:52)
	at org.testng.SuiteRunnerWorker.run(SuiteRunnerWorker.java:86)
	at org.testng.TestNG.runSuitesSequentially(TestNG.java:1215)
	at org.testng.TestNG.runSuitesLocally(TestNG.java:1140)
	at org.testng.TestNG.run(TestNG.java:1048)
	at org.testng.remote.AbstractRemoteTestNG.run(AbstractRemoteTestNG.java:114)
	at org.testng.remote.RemoteTestNG.initAndRun(RemoteTestNG.java:251)
	at org.testng.remote.RemoteTestNG.main(RemoteTestNG.java:77)
]]>
    </failure>
  </testcase> <!-- User_Submenu -->
  <testcase name="Customer_Addrecord_button" time="0.043" classname="USERS.User_page">
    <failure type="java.lang.AssertionError" message="expected [null] but found [Add Record]">
      <![CDATA[java.lang.AssertionError: expected [null] but found [Add Record]
	at org.testng.Assert.fail(Assert.java:94)
	at org.testng.Assert.failNotEquals(Assert.java:496)
	at org.testng.Assert.assertEquals(Assert.java:116)
	at org.testng.Assert.assertEquals(Assert.java:178)
	at org.testng.Assert.assertEquals(Assert.java:188)
	at USERS.User_page.Customer_Addrecord_button(User_page.java:317)
	at sun.reflect.NativeMethodAccessorImpl.invoke0(Native Method)
	at sun.reflect.NativeMethodAccessorImpl.invoke(Unknown Source)
	at sun.reflect.DelegatingMethodAccessorImpl.invoke(Unknown Source)
	at java.lang.reflect.Method.invoke(Unknown Source)
	at org.testng.internal.MethodInvocationHelper.invokeMethod(MethodInvocationHelper.java:85)
	at org.testng.internal.Invoker.invokeMethod(Invoker.java:639)
	at org.testng.internal.Invoker.invokeTestMethod(Invoker.java:816)
	at org.testng.internal.Invoker.invokeTestMethods(Invoker.java:1124)
	at org.testng.internal.TestMethodWorker.invokeTestMethods(TestMethodWorker.java:125)
	at org.testng.internal.TestMethodWorker.run(TestMethodWorker.java:108)
	at org.testng.TestRunner.privateRun(TestRunner.java:774)
	at org.testng.TestRunner.run(TestRunner.java:624)
	at org.testng.SuiteRunner.runTest(SuiteRunner.java:359)
	at org.testng.SuiteRunner.runSequentially(SuiteRunner.java:354)
	at org.testng.SuiteRunner.privateRun(SuiteRunner.java:312)
	at org.testng.SuiteRunner.run(SuiteRunner.java:261)
	at org.testng.SuiteRunnerWorker.runSuite(SuiteRunnerWorker.java:52)
	at org.testng.SuiteRunnerWorker.run(SuiteRunnerWorker.java:86)
	at org.testng.TestNG.runSuitesSequentially(TestNG.java:1215)
	at org.testng.TestNG.runSuitesLocally(TestNG.java:1140)
	at org.testng.TestNG.run(TestNG.java:1048)
	at org.testng.remote.AbstractRemoteTestNG.run(AbstractRemoteTestNG.java:114)
	at org.testng.remote.RemoteTestNG.initAndRun(RemoteTestNG.java:251)
	at org.testng.remote.RemoteTestNG.main(RemoteTestNG.java:77)
]]>
    </failure>
  </testcase> <!-- Customer_Addrecord_button -->
  <testcase name="AddRecord_Alertmessage" time="2.052" classname="USERS.User_page">
    <error type="java.lang.NullPointerException">
      <![CDATA[java.lang.NullPointerException
	at USERS.User_page.AddRecord_Alertmessage(User_page.java:369)
	at sun.reflect.NativeMethodAccessorImpl.invoke0(Native Method)
	at sun.reflect.NativeMethodAccessorImpl.invoke(Unknown Source)
	at sun.reflect.DelegatingMethodAccessorImpl.invoke(Unknown Source)
	at java.lang.reflect.Method.invoke(Unknown Source)
	at org.testng.internal.MethodInvocationHelper.invokeMethod(MethodInvocationHelper.java:85)
	at org.testng.internal.Invoker.invokeMethod(Invoker.java:639)
	at org.testng.internal.Invoker.invokeTestMethod(Invoker.java:816)
	at org.testng.internal.Invoker.invokeTestMethods(Invoker.java:1124)
	at org.testng.internal.TestMethodWorker.invokeTestMethods(TestMethodWorker.java:125)
	at org.testng.internal.TestMethodWorker.run(TestMethodWorker.java:108)
	at org.testng.TestRunner.privateRun(TestRunner.java:774)
	at org.testng.TestRunner.run(TestRunner.java:624)
	at org.testng.SuiteRunner.runTest(SuiteRunner.java:359)
	at org.testng.SuiteRunner.runSequentially(SuiteRunner.java:354)
	at org.testng.SuiteRunner.privateRun(SuiteRunner.java:312)
	at org.testng.SuiteRunner.run(SuiteRunner.java:261)
	at org.testng.SuiteRunnerWorker.runSuite(SuiteRunnerWorker.java:52)
	at org.testng.SuiteRunnerWorker.run(SuiteRunnerWorker.java:86)
	at org.testng.TestNG.runSuitesSequentially(TestNG.java:1215)
	at org.testng.TestNG.runSuitesLocally(TestNG.java:1140)
	at org.testng.TestNG.run(TestNG.java:1048)
	at org.testng.remote.AbstractRemoteTestNG.run(AbstractRemoteTestNG.java:114)
	at org.testng.remote.RemoteTestNG.initAndRun(RemoteTestNG.java:251)
	at org.testng.remote.RemoteTestNG.main(RemoteTestNG.java:77)
]]>
    </error>
  </testcase> <!-- AddRecord_Alertmessage -->
</testsuite> <!-- USERS.User_page -->
